Workbook

Sheet Données brutes
A1: Variables | B1: 1900 | C1: 1901 | D1: 1902 | E1: 1903 | F1: 1904 | G1: 1905 | H1: 1906 | I1: 1907 | J1: 1908 | K1: 1909 | L1: 1910 | M1: 1911 | N1: 1912 | O1: 1913 | P1: 1914 | Q1: 1915 | R1: 1916 | S1: 1917 | T1: 1918 | U1: 1919 | V1: 1920 | W1: 1921 | X1: 1922 | Y1: 1923 | Z1: 1924 | AA1: 1925 | AB1: 1926 | AC1: 1927 | AD1: 1928 | AE1: 1929 | AF1: 1930 | AG1: 1931 | AH1: 1932 | AI1: 1933 | AJ1: 1934 | AK1: 1935 | AL1: 1936 | AM1: 1937 | AN1: 1938 | AO1: 1939 | AP1: 1940 | AQ1: 1941 | AR1: 1942 | AS1: 1943 | AT1: 1944 | AU1: 1945 | AV1: 1946 | AW1: 1947 | AX1: 1948 | AY1: 1949 | AZ1: 1950 | BA1: 1951 | BB1: 1952 | BC1: 1953 | BD1: 1954 | BE1: 1955 | BF1: 1956 | BG1: 1957 | BH1: 1958 | BI1: 1959 | BJ1: 1960 | BK1: 1961 | BL1: 1962 | BM1: 1963 | BN1: 1964 | BO1: 1965 | BP1: 1966 | BQ1: 1967 | BR1: 1968 | BS1: 1969 | BT1: 1970 | BU1: 1971 | BV1: 1972 | BW1: 1973 | BX1: 1974 | BY1: 1975 | BZ1: 1976 | CA1: 1977 | CB1: 1978 | CC1: 1979 | CD1: 1980 | CE1: 1981 | CF1: 1982 | CG1: 1983 | CH1: 1984 | CI1: 1985 | CJ1: 1986 | CK1: 1987 | CL1: 1988 | CM1: 1989 | CN1: 1990 | CO1: 1991 | CP1: 1992 | CQ1: 1993 | CR1: 1994 | CS1: 1995 | CT1: 1996 | CU1: 1997 | CV1: 1998 | CW1: 1999 | CX1: 2000 | CY1: 2001 | CZ1: 2002 | DA1: 2003 | DB1: 2004 | DC1: 2005 | DD1: 2006 | DE1: 2007 | DF1: 2008 | DG1: 2009 | DH1: 2010 | DI1: 2011 | DJ1: 2012 | DK1: 2013 | DL1: 2014 | DM1: 2015 | DN1: 2016 | DO1: 2017 | DP1: 2018 | DQ1: 2019 | DR1: 2020 | DS1: 2021 | DT1: 2022
A2: Déficit public | CB2: -1.79682457725571 | CC2: -0.4821576555084 | CD2: -0.428536644752861 | CE2: -2.40752178985656 | CF2: -2.83691332089851 | CG2: -2.54076788744866 | CH2: -2.73595179836782 | CI2: -2.97245967672752 | CJ2: -3.1974131962347 | CK2: -2.01429233991797 | CL2: -2.56437692860578 | CM2: -1.7822310431733 | CN2: -2.43397060973133 | CO2: -2.86304450378078 | CP2: -4.60121858595576 | CQ2: -6.3587944863889 | CR2: -5.42289936069065 | CS2: -5.10854299487882 | CT2: -3.90587942178419 | CU2: -3.65283417016237 | CV2: -2.37843739459248 | CW2: -1.60292762521601 | CX2: -1.31842268114447 | CY2: -1.37927447666103 | CZ2: -3.1602899304648 | DA2: -4.0155372099498 | DB2: -3.59057029293687 | DC2: -3.35555989704995 | DD2: -2.44368560794004 | DE2: -2.63629620472246 | DF2: -3.26373482970116 | DG2: -7.17477905126052 | DH2: -6.88672167290052 | DI2: -5.15476088106651 | DJ2: -4.98098433361866 | DK2: -4.08409452344595 | DL2: -3.90465934648671 | DM2: -3.62517466994658 | DN2: -3.63725639835479 | DO2: -2.95841709319262 | DP2: -2.28895454080005 | DQ2: -3.06465077831587 | DR2: -9.0856587026567
A3: ConsoFinale | BJ3: 5 | BK3: 5.8 | BL3: 7.4 | BM3: 7.2 | BN3: 5.5 | BO3: 3.9 | BP3: 4.8 | BQ3: 5 | BR3: 4.3 | BS3: 6.4 | BT3: 4.5 | BU3: 5.6 | BV3: 5.2 | BW3: 5.7 | BX3: 2.8 | BY3: 2 | BZ3: 5.6 | CA3: 2.6 | CB3: 3.9 | CC3: 3.4 | CD3: 1.2 | CE3: 2 | CF3: 3.3 | CG3: 0.8 | CH3: 0.7 | CI3: 1.9 | CJ3: 3.7 | CK3: 3.2 | CL3: 3.3 | CM3: 3.2 | CN3: 2.5 | CO3: 0.6 | CP3: 0.9 | CQ3: -0.1 | CR3: 1.6 | CS3: 1.6 | CT3: 1.9 | CU3: 0.5 | CV3: 4 | CW3: 3.5 | CX3: 3.6 | CY3: 2.5 | CZ3: 1.8 | DA3: 1.7 | DB3: 2.1 | DC3: 2.5 | DD3: 2.1 | DE3: 2.6 | DF3: 0.6 | DG3: 0.2 | DH3: 1.8 | DI3: 0.6 | DJ3: -0.5 | DK3: 0.5 | DL3: 0.8 | DM3: 1.5 | DN3: 1.8 | DO3: 1.4 | DP3: 0.9
A4: Dépense Publique | BJ4: 34.686265 | BK4: 36.033836 | BL4: 37.175276 | BM4: 37.936407 | BN4: 38.368911 | BO4: 39.098689 | BP4: 39.275297 | BQ4: 39.940812 | BR4: 41.889496 | BS4: 40.738374 | BT4: 40.022848 | BU4: 39.647712 | BV4: 39.44793 | BW4: 39.353141 | BX4: 39.757364 | BY4: 44.523394 | BZ4: 44.988882 | CA4: 44.192292 | CB4: 45.196499 | CC4: 45.471759 | CD4: 46.404576 | CE4: 48.957293 | CF4: 48.957293 | CG4: 50.744306 | CH4: 51.67365 | CI4: 52.31168 | CJ4: 51.901304 | CK4: 51.3188 | CL4: 50.643677 | CM4: 49.472942 | CN4: 50.132239 | CO4: 51.271534 | CP4: 52.591223 | CQ4: 55.204517 | CR4: 54.625305 | CS4: 54.808833 | CT4: 54.881014 | CU4: 54.5306 | CV4: 52.924493 | CW4: 52.630005 | CX4: 51.652286 | CY4: 51.71831 | CZ4: 52.795162 | DA4: 53.270449 | DB4: 52.984929 | DC4: 53.294036 | DD4: 52.875721 | DE4: 52.565464 | DF4: 53.296259 | DG4: 57.151841 | DH4: 56.881785 | DI4: 56.290687 | DJ4: 57.107262 | DK4: 57.2278 | DL4: 57.213602 | DM4: 56.8 | DN4: 56.7 | DO4: 56.5 | DP4: 55.6 | DQ4: 55.4 | DR4: 61.6
A5: Dette Publique | CS5: 67.29042 | CT5: 73.29137 | CU5: 75.95255 | CV5: 77.6053 | CW5: 74.01518 | CX5: 72.42918 | CY5: 71.47308 | CZ5: 75.16156 | DA5: 79.07757 | DB5: 80.54945 | DC5: 82.14224 | DD5: 77.26933 | DE5: 75.94181 | DF5: 82.50349 | DG5: 97.5731 | DH5: 100.9953 | DI5: 103.8066 | DJ5: 111.9382 | DK5: 112.4676 | DL5: 120.1551 | DM5: 120.8252 | DN5: 123.6707 | DO5: 122.9442 | DP5: 120.7452 | DQ5: 123.088 | DR5: 145.808
A6: Dépenses retraite | CD6: 9.25 | CE6: 9.511 | CF6: 9.713 | CG6: 9.883 | CH6: 10.108 | CI6: 10.298 | CJ6: 10.271 | CK6: 10.288 | CL6: 10.364 | CM6: 9.845 | CN6: 10.42 | CO6: 10.69 | CP6: 11.012 | CQ6: 11.5 | CR6: 11.625 | CS6: 11.801 | CT6: 11.934 | CU6: 11.916 | CV6: 11.777 | CW6: 11.774 | CX6: 11.482 | CY6: 11.476 | CZ6: 11.622 | DA6: 11.79 | DB6: 11.84 | DC6: 12.021 | DD6: 11.797 | DE6: 11.889 | DF6: 12.179 | DG6: 13.093 | DH6: 13.18 | DI6: 13.299 | DJ6: 13.566 | DK6: 13.796 | DL6: 13.87 | DM6: 13.798 | DN6: 13.803 | DO6: 13.641 | DP6: 13.596
A7: Productivité multifactorielle (PGF) | CI7: 2.500633 | CJ7: 1.300588 | CK7: 0.396134 | CL7: 2.425775 | CM7: 2.46192 | CN7: 1.203488 | CO7: 0.008888 | CP7: 1.077727 | CQ7: -0.311711 | CR7: 1.310426 | CS7: 1.565742 | CT7: 0.337699 | CU7: 0.964785 | CV7: 1.726729 | CW7: 0.791836 | CX7: 1.778101 | CY7: 0.74156 | CZ7: 1.56464 | DA7: -0.1163 | DB7: 0.805397 | DC7: 0.360297 | DD7: 1.693613 | DE7: -0.630568 | DF7: -1.29498 | DG7: -2.001751 | DH7: 0.908047 | DI7: 0.755023 | DJ7: -0.26594 | DK7: 0.581438 | DL7: 0.418421 | DM7: 0.318398 | DN7: -0.110433 | DO7: 1.469885 | DP7: 0.043905 | DQ7: 0.092581
A8: Dépense Education | CD8: 6.5 | CE8: 6.7 | CF8: 6.8 | CG8: 6.8 | CH8: 6.9 | CI8: 6.9 | CJ8: 6.8 | CK8: 6.7 | CL8: 6.6 | CM8: 6.5 | CN8: 6.7 | CO8: 7 | CP8: 7.4 | CQ8: 7.6 | CR8: 7.7 | CS8: 7.7 | CT8: 7.7 | CU8: 7.7 | CV8: 7.6 | CW8: 7.5 | CX8: 7.3 | CY8: 7.2 | CZ8: 7.2 | DA8: 7.1 | DB8: 7 | DC8: 6.9 | DD8: 6.8 | DE8: 6.6 | DF8: 6.7 | DG8: 7.1 | DH8: 7 | DI8: 6.8 | DJ8: 6.7 | DK8: 6.8 | DL8: 6.8 | DM8: 6.7 | DN8: 6.7 | DO8: 6.7 | DP8: 6.7 | DQ8: 6.6
A9: ImpotSalaire | BO9: 1.556 | BP9: 1.546 | BQ9: 1.57 | BR9: 1.483 | BS9: 0.457 | BT9: 0.405 | BU9: 0.427 | BV9: 0.459 | BW9: 0.521 | BX9: 0.542 | BY9: 0.679 | BZ9: 0.728 | CA9: 0.815 | CB9: 0.865 | CC9: 0.831 | CD9: 0.871 | CE9: 0.879 | CF9: 0.909 | CG9: 0.924 | CH9: 0.973 | CI9: 0.865 | CJ9: 0.836 | CK9: 0.824 | CL9: 0.757 | CM9: 0.775 | CN9: 0.783 | CO9: 0.792 | CP9: 0.877 | CQ9: 0.939 | CR9: 1 | CS9: 1.052 | CT9: 1.078 | CU9: 1.117 | CV9: 1.036 | CW9: 1.04 | CX9: 1.006 | CY9: 0.986 | CZ9: 1.04 | DA9: 1.054 | DB9: 1.097 | DC9: 1.147 | DD9: 1.141 | DE9: 1.172 | DF9: 1.217 | DG9: 1.319 | DH9: 1.342 | DI9: 1.344 | DJ9: 1.414 | DK9: 1.578 | DL9: 1.593 | DM9: 1.564 | DN9: 1.549 | DO9: 1.548 | DP9: 1.51 | DQ9: 1.779 | DR9: 1.891
A10: PaiementInteret | BV10: 1.4935065 | BW10: 1.2445731 | BX10: 1.3814095 | BY10: 2.1563342 | BZ10: 1.9211659 | CA10: 2.0527005 | CB10: 2.1682243 | CC10: 2.3403796 | CD10: 2.1747177 | CE10: 3.1759459 | CF10: 3.1793602 | CG10: 4.1316123 | CH10: 4.2263874 | CI10: 4.544791 | CJ10: 4.6268246 | CK10: 4.4163548 | CL10: 4.3347014 | CM10: 4.6744443 | CN10: 5.1825984 | CO10: 5.3092425 | CP10: 5.7670464 | CQ10: 6.0566303 | CR10: 6.3864854 | CS10: 6.3613878 | CT10: 6.570223 | CU10: 6.5523008 | CV10: 6.6214767 | CW10: 6.2214039 | CX10: 6.1810539 | CY10: 6.1482712 | CZ10: 6.0456311 | DA10: 5.7582657 | DB10: 5.727949 | DC10: 5.6738141 | DD10: 5.4360695 | DE10: 5.5674493 | DF10: 5.7719818 | DG10: 4.9240269 | DH10: 4.9820289 | DI10: 5.4338469 | DJ10: 5.1965741 | DK10: 4.5943277 | DL10: 4.3570569 | DM10: 4.0515757 | DN10: 3.79072 | DO10: 3.576838 | DP10: 3.5837305 | DQ10: 3.0560622
A11: StockCapital | AZ11: 2593791.5 | BA11: 2655761.2 | BB11: 2715599.2 | BC11: 2775168 | BD11: 2855737.5 | BE11: 2950121 | BF11: 3061268.2 | BG11: 3189814.5 | BH11: 3332971.8 | BI11: 3465297.8 | BJ11: 3638361.5 | BK11: 3812752.2 | BL11: 4006590.5 | BM11: 4212689.5 | BN11: 4451621 | BO11: 4688170.5 | BP11: 4947385.5 | BQ11: 5216563.5 | BR11: 5494700.5 | BS11: 5810064.5 | BT11: 6132885 | BU11: 6471339.5 | BV11: 6820245.5 | BW11: 7187111 | BX11: 7546950 | BY11: 7856808 | BZ11: 8160465 | CA11: 8441035 | CB11: 8720247 | CC11: 9000279 | CD11: 9281641 | CE11: 9541136 | CF11: 9781079 | CG11: 9990670 | CH11: 10184454 | CI11: 10379602 | CJ11: 10585801 | CK11: 10808423 | CL11: 11068552 | CM11: 11358359 | CN11: 11658941 | CO11: 11934365 | CP11: 12180696 | CQ11: 12374120 | CR11: 12566522 | CS11: 12755864 | CT11: 12937552 | CU11: 13110580 | CV11: 13309447 | CW11: 13542147 | CX11: 13801955 | CY11: 14057476 | CZ11: 14286074 | DA11: 14514070 | DB11: 14754241 | DC11: 15002391 | DD11: 15264812 | DE11: 15556713 | DF11: 15838762 | DG11: 16031712 | DH11: 16233568 | DI11: 16442443 | DJ11: 16643017 | DK11: 16827310 | DL11: 17002716 | DM11: 17175696 | DN11: 17357434 | DO11: 17562930 | DP11: 17778742 | DQ11: 18013436
A12: Investissement | BJ12: 22.575479 | BK12: 23.919252 | BL12: 23.702246 | BM12: 24.541493 | BN12: 25.455445 | BO12: 25.830258 | BP12: 26.145172 | BQ12: 26.562064 | BR12: 26.268644 | BS12: 25.995408 | BT12: 25.675031 | BU12: 25.890921 | BV12: 26.007911 | BW12: 26.255885 | BX12: 26.851892 | BY12: 25.429887 | BZ12: 24.995965 | CA12: 24.101797 | CB12: 23.657903 | CC12: 23.586801 | CD12: 24.428138 | CE12: 23.918547 | CF12: 23.245146 | CG12: 21.940717 | CH12: 21.294429 | CI12: 21.180986 | CJ12: 21.226227 | CK12: 21.855341 | CL12: 22.619283 | CM12: 23.164892 | CN12: 23.382652 | CO12: 23.178423 | CP12: 22.08088 | CQ12: 20.706336 | CR12: 20.423658 | CS12: 20.074154 | CT12: 19.860078 | CU12: 19.519376 | CV12: 19.901087 | CW12: 20.809294 | CX12: 21.514353 | CY12: 21.513392 | CZ12: 20.95339 | DA12: 21.034841 | DB12: 21.364609 | DC12: 21.797435 | DD12: 22.450709 | DE12: 23.182666 | DF12: 23.596051 | DG12: 22.067504 | DH12: 22.105419 | DI12: 22.423871 | DJ12: 22.458115 | DK12: 22.041868 | DL12: 21.819734 | DM12: 21.499278 | DN12: 21.815303 | DO12: 22.495845 | DP12: 22.892634 | DQ12: 23.477387 | DR12: 22.964748
A13: TVA | CS13: 89.361 | CT13: 96.097 | CU13: 98.936 | CV13: 101.856 | CW13: 105.97 | CX13: 107.164 | CY13: 108.581 | CZ13: 110.413 | DA13: 113.622 | DB13: 120.224 | DC13: 126.624 | DD13: 131.693 | DE13: 136.542 | DF13: 137.737 | DG13: 130.303 | DH13: 135.578 | DI13: 140.552 | DJ13: 142.527 | DK13: 144.49 | DL13: 148.454 | DM13: 151.68 | DN13: 154.49 | DO13: 162.011 | DP13: 167.72 | DQ13: 173.953 | DR13: 161.122
A14: Dépenses Santé | CX14: 9.5844774 | CY14: 9.7056274 | CZ14: 10.022186 | DA14: 10.082833 | DB14: 10.164293 | DC14: 10.214845 | DD14: 10.385665 | DE14: 10.315644 | DF14: 10.500847 | DG14: 11.287562 | DH14: 11.225602 | DI14: 11.184977 | DJ14: 11.2974 | DK14: 11.41635 | DL14: 11.544416 | DM14: 11.447556 | DN14: 11.471637 | DO14: 11.332762 | DP14: 11.18583 | DQ14: 11.057472

Sheet Données brutes V2
A1: Variables | B1: Déficit public | C1: ConsoFinale | D1: Dépense Publique | E1: Dette Publique | F1: Dépenses retraite | G1: Productivité multifactorielle (PGF) | H1: Dépense Education | I1: ImpotSalaire | J1: PaiementInteret | K1: StockCapital | L1: Investissement | M1: TVA | N1: Dépenses Santé
A2: 1900
A3: 1901
A4: 1902
A5: 1903
A6: 1904
A7: 1905
A8: 1906
A9: 1907
A10: 1908
A11: 1909
A12: 1910
A13: 1911
... A51: 1949
A52: 1950 | K52: 2593791.5
A53: 1951 | K53: 2655761.2
A54: 1952 | K54: 2715599.2
A55: 1953 | K55: 2775168
A56: 1954 | K56: 2855737.5
A57: 1955 | K57: 2950121
A58: 1956 | K58: 3061268.2
A59: 1957 | K59: 3189814.5
A60: 1958 | K60: 3332971.8
A61: 1959 | K61: 3465297.8
A62: 1960 | C62: 5 | D62: 34.686265 | K62: 3638361.5 | L62: 22.575479
A63: 1961 | C63: 5.8 | D63: 36.033836 | K63: 3812752.2 | L63: 23.919252
A64: 1962 | C64: 7.4 | D64: 37.175276 | K64: 4006590.5 | L64: 23.702246
A65: 1963 | C65: 7.2 | D65: 37.936407 | K65: 4212689.5 | L65: 24.541493
A66: 1964 | C66: 5.5 | D66: 38.368911 | K66: 4451621 | L66: 25.455445
A67: 1965 | C67: 3.9 | D67: 39.098689 | I67: 1.556 | K67: 4688170.5 | L67: 25.830258
A68: 1966 | C68: 4.8 | D68: 39.275297 | I68: 1.546 | K68: 4947385.5 | L68: 26.145172
A69: 1967 | C69: 5 | D69: 39.940812 | I69: 1.57 | K69: 5216563.5 | L69: 26.562064
A70: 1968 | C70: 4.3 | D70: 41.889496 | I70: 1.483 | K70: 5494700.5 | L70: 26.268644
A71: 1969 | C71: 6.4 | D71: 40.738374 | I71: 0.457 | K71: 5810064.5 | L71: 25.995408
A72: 1970 | C72: 4.5 | D72: 40.022848 | I72: 0.405 | K72: 6132885 | L72: 25.675031
A73: 1971 | C73: 5.6 | D73: 39.647712 | I73: 0.427 | K73: 6471339.5 | L73: 25.890921
A74: 1972 | C74: 5.2 | D74: 39.44793 | I74: 0.459 | J74: 1.4935065 | K74: 6820245.5 | L74: 26.007911
A75: 1973 | C75: 5.7 | D75: 39.353141 | I75: 0.521 | J75: 1.2445731 | K75: 7187111 | L75: 26.255885
A76: 1974 | C76: 2.8 | D76: 39.757364 | I76: 0.542 | J76: 1.3814095 | K76: 7546950 | L76: 26.851892
A77: 1975 | C77: 2 | D77: 44.523394 | I77: 0.679 | J77: 2.1563342 | K77: 7856808 | L77: 25.429887
...

Sheet Quinq
A1: Variables | B1: Déficit public | C1: ConsoFinale | D1: Dépense Publique | E1: Dette Publique | F1: Dépenses retraite | G1: Productivité multifactorielle (PGF) | H1: Dépense Education | I1: ImpotSalaire | J1: PaiementInteret | K1: StockCapital | L1: Investissement | M1: TVA | N1: Dépenses santé
A2: 1900
A3: 1905
A4: 1910
A5: 1915
A6: 1920
A7: 1925
A8: 1930
A9: 1935
A10: 1940
A11: 1945
A12: 1950 | K12: =AVERAGE('Données brutes V2'!K52:K56) -> 2719211.5
A13: 1955 | K13: =AVERAGE('Données brutes V2'!K57:K61) -> 3199894.6
A14: 1960 | C14: =AVERAGE('Données brutes V2'!C62:C66) -> 6.18 | D14: =AVERAGE('Données brutes V2'!D62:D66) -> 36.840139 | K14: =AVERAGE('Données brutes V2'!K62:K66) -> 4024403 | L14: =AVERAGE('Données brutes V2'!L62:L66) -> 24.038783
A15: 1965 | C15: =AVERAGE('Données brutes V2'!C67:C71) -> 4.88 | D15: =AVERAGE('Données brutes V2'!D67:D71) -> 40.188533 | I15: =AVERAGE('Données brutes V2'!I67:I71) -> 1.3224 | K15: =AVERAGE('Données brutes V2'!K67:K71) -> 5231376.9 | L15: =AVERAGE('Données brutes V2'!L67:L71) -> 26.160309
A16: 1970 | C16: =AVERAGE('Données brutes V2'!C72:C76) -> 4.76 | D16: =AVERAGE('Données brutes V2'!D72:D76) -> 39.645799 | I16: =AVERAGE('Données brutes V2'!I72:I76) -> 0.4708 | J16: =AVERAGE('Données brutes V2'!J72:J76) -> 1.373163 | K16: =AVERAGE('Données brutes V2'!K72:K76) -> 6831706.2 | L16: =AVERAGE('Données brutes V2'!L72:L76) -> 26.136328
A17: 1975 | B17: =AVERAGE('Données brutes V2'!B77:B81) -> -1.1394911 | C17: =AVERAGE('Données brutes V2'!C77:C81) -> 3.5 | D17: =AVERAGE('Données brutes V2'!D77:D81) -> 44.874565 | I17: =AVERAGE('Données brutes V2'!I77:I81) -> 0.7836 | J17: =AVERAGE('Données brutes V2'!J77:J81) -> 2.1277609 | K17: =AVERAGE('Données brutes V2'!K77:K81) -> 8435766.8 | L17: =AVERAGE('Données brutes V2'!L77:L81) -> 24.354471
A18: 1980 | B18: =AVERAGE('Données brutes V2'!B82:B86) -> -2.1899383 | C18: =AVERAGE('Données brutes V2'!C82:C86) -> 1.6 | D18: =AVERAGE('Données brutes V2'!D82:D86) -> 49.347424 | F18: =AVERAGE('Données brutes V2'!F82:F86) -> 9.693 | H18: =AVERAGE('Données brutes V2'!H82:H86) -> 6.74 | I18: =AVERAGE('Données brutes V2'!I82:I86) -> 0.9112 | J18: =AVERAGE('Données brutes V2'!J82:J86) -> 3.3776047 | K18: =AVERAGE('Données brutes V2'!K82:K86) -> 9755796 | L18: =AVERAGE('Données brutes V2'!L82:L86) -> 22.965395
A19: 1985 | B19: =AVERAGE('Données brutes V2'!B87:B91) -> -2.5061546 | C19: =AVERAGE('Données brutes V2'!C87:C91) -> 3.06 | D19: =AVERAGE('Données brutes V2'!D87:D91) -> 51.129681 | F19: =AVERAGE('Données brutes V2'!F87:F91) -> 10.2132 | G19: =AVERAGE('Données brutes V2'!G87:G91) -> 1.81701 | H19: =AVERAGE('Données brutes V2'!H87:H91) -> 6.7 | I19: =AVERAGE('Données brutes V2'!I87:I91) -> 0.8114 | J19: =AVERAGE('Données brutes V2'!J87:J91) -> 4.5194232 | K19: =AVERAGE('Données brutes V2'!K87:K91) -> 10840147 | L19: =AVERAGE('Données brutes V2'!L87:L91) -> 22.009346
A20: 1990 | B20: =AVERAGE('Données brutes V2'!B92:B96) -> -4.3359855 | C20: =AVERAGE('Données brutes V2'!C92:C96) -> 1.1 | D20: =AVERAGE('Données brutes V2'!D92:D96) -> 52.764963 | F20: =AVERAGE('Données brutes V2'!F92:F96) -> 11.0494 | G20: =AVERAGE('Données brutes V2'!G92:G96) -> 0.6577636 | H20: =AVERAGE('Données brutes V2'!H92:H96) -> 7.28 | I20: =AVERAGE('Données brutes V2'!I92:I96) -> 0.8782 | J20: =AVERAGE('Données brutes V2'!J92:J96) -> 5.7404006 | K20: =AVERAGE('Données brutes V2'!K92:K96) -> 12142929 | L20: =AVERAGE('Données brutes V2'!L92:L96) -> 21.95439
A21: 1995 | B21: =AVERAGE('Données brutes V2'!B97:B101) -> -3.3297243 | C21: =AVERAGE('Données brutes V2'!C97:C101) -> 2.3 | D21: =AVERAGE('Données brutes V2'!D97:D101) -> 53.954989 | E21: =AVERAGE('Données brutes V2'!E97:E101) -> 73.630964 | F21: =AVERAGE('Données brutes V2'!F97:F101) -> 11.8404 | G21: =AVERAGE('Données brutes V2'!G97:G101) -> 1.0773582 | H21: =AVERAGE('Données brutes V2'!H97:H101) -> 7.64 | I21: =AVERAGE('Données brutes V2'!I97:I101) -> 1.0646 | ... M21: =AVERAGE('Données brutes V2'!M97:M101) -> 98.444
A22: 2000 | B22: =AVERAGE('Données brutes V2'!B102:B106) -> -2.6928189 | C22: =AVERAGE('Données brutes V2'!C102:C106) -> 2.34 | D22: =AVERAGE('Données brutes V2'!D102:D106) -> 52.484227 | E22: =AVERAGE('Données brutes V2'!E102:E106) -> 75.738168 | F22: =AVERAGE('Données brutes V2'!F102:F106) -> 11.642 | G22: =AVERAGE('Données brutes V2'!G102:G106) -> 0.9546796 | H22: =AVERAGE('Données brutes V2'!H102:H106) -> 7.16 | I22: =AVERAGE('Données brutes V2'!I102:I106) -> 1.0366 | ... N22: =AVERAGE('Données brutes V2'!N102:N106) -> 9.9118835
A23: 2005 | B23: =AVERAGE('Données brutes V2'!B107:B111) -> -3.7748111 | C23: =AVERAGE('Données brutes V2'!C107:C111) -> 1.6 | D23: =AVERAGE('Données brutes V2'!D107:D111) -> 53.836664 | E23: =AVERAGE('Données brutes V2'!E107:E111) -> 83.085994 | F23: =AVERAGE('Données brutes V2'!F107:F111) -> 12.1958 | G23: =AVERAGE('Données brutes V2'!G107:G111) -> -0.3746778 | H23: =AVERAGE('Données brutes V2'!H107:H111) -> 6.82 | I23: =AVERAGE('Données brutes V2'!I107:I111) -> 1.1992 | ... N23: =AVERAGE('Données brutes V2'!N107:N111) -> 10.540913
A24: 2010 | B24: =AVERAGE('Données brutes V2'!B112:B116) -> -5.0022442 | C24: =AVERAGE('Données brutes V2'!C112:C116) -> 0.64 | D24: =AVERAGE('Données brutes V2'!D112:D116) -> 56.944227 | E24: =AVERAGE('Données brutes V2'!E112:E116) -> 109.87256 | F24: =AVERAGE('Données brutes V2'!F112:F116) -> 13.5422 | G24: =AVERAGE('Données brutes V2'!G112:G116) -> 0.4793978 | H24: =AVERAGE('Données brutes V2'!H112:H116) -> 6.82 | I24: =AVERAGE('Données brutes V2'!I112:I116) -> 1.4542 | ... N24: =AVERAGE('Données brutes V2'!N112:N116) -> 11.333749
A25: 2015 | B25: =AVERAGE('Données brutes V2'!B117:B121) -> -3.1148907 | C25: =AVERAGE('Données brutes V2'!C117:C121) -> 1.4 | D25: =AVERAGE('Données brutes V2'!D117:D121) -> 56.2 | E25: =AVERAGE('Données brutes V2'!E117:E121) -> 122.25466 | F25: =AVERAGE('Données brutes V2'!F117:F121) -> 13.7095 | G25: =AVERAGE('Données brutes V2'!G117:G121) -> 0.3628672 | H25: =AVERAGE('Données brutes V2'!H117:H121) -> 6.68 | I25: =AVERAGE('Données brutes V2'!I117:I121) -> 1.59 | ... N25: =AVERAGE('Données brutes V2'!N117:N121) -> 11.299051
A26: 2020 | B26: =AVERAGE('Données brutes V2'!B122:B126) -> -9.0856587 | D26: =AVERAGE('Données brutes V2'!D122:D126) -> 61.6 | E26: =AVERAGE('Données brutes V2'!E122:E126) -> 145.808 | I26: =AVERAGE('Données brutes V2'!I122:I126) -> 1.891 | L26: =AVERAGE('Données brutes V2'!L122:L126) -> 22.964748 | M26: =AVERAGE('Données brutes V2'!M122:M126) -> 161.122
